Microsoft Windows [Version 10.0.17763.475]
(c) 2018 Microsoft Corporation. All rights reserved.

C:\Users\dyree>cd\

C:\>cd windows\system32

C:\Windows\System32>cd..

C:\Windows>e:

E:\>cd school

E:\School>cd python

E:\School\Python>mkdir django-projects
A subdirectory or file django-projects already exists.

E:\School\Python>mkdir django-projects2

E:\School\Python>cd django-projects2

E:\School\Python\django-projects2>python
Python 3.7.3 (v3.7.3:ef4ec6ed12, Mar 25 2019, 22:22:05) [MSC v.1916 64 bit (AMD64)] on win32
Type "help", "copyright", "credits" or "license" for more information.
>>> exit()

E:\School\Python\django-projects2>python -m venv envtwo

E:\School\Python\django-projects2>envtwo\Scripts\activate

(envtwo) E:\School\Python\django-projects2>pip intall django
ERROR: unknown command "intall" - maybe you meant "install"

(envtwo) E:\School\Python\django-projects2>pip install django
Collecting django
  Using cached https://files.pythonhosted.org/packages/b1/1d/2476110614367adfb079a9bc718621f9fc8351e9214e1750cae1832d4090/Django-2.2.1-py3-none-any.whl
Collecting sqlparse (from django)
  Using cached https://files.pythonhosted.org/packages/ef/53/900f7d2a54557c6a37886585a91336520e5539e3ae2423ff1102daf4f3a7/sqlparse-0.3.0-py2.py3-none-any.whl
Collecting pytz (from django)
  Using cached https://files.pythonhosted.org/packages/3d/73/fe30c2daaaa0713420d0382b16fbb761409f532c56bdcc514bf7b6262bb6/pytz-2019.1-py2.py3-none-any.whl
Installing collected packages: sqlparse, pytz, django
Successfully installed django-2.2.1 pytz-2019.1 sqlparse-0.3.0
You are using pip version 19.0.3, however version 19.1.1 is available.
You should consider upgrading via the 'python -m pip install --upgrade pip' command.

(envtwo) E:\School\Python\django-projects2>dectivate
'dectivate' is not recognized as an internal or external command,
operable program or batch file.

(envtwo) E:\School\Python\django-projects2>pip install --upgrade pip
Collecting pip
  Using cached https://files.pythonhosted.org/packages/5c/e0/be401c003291b56efc55aeba6a80ab790d3d4cece2778288d65323009420/pip-19.1.1-py2.py3-none-any.whl
Installing collected packages: pip
  Found existing installation: pip 19.0.3
    Uninstalling pip-19.0.3:
Could not install packages due to an EnvironmentError: [WinError 5] Access is denied: 'e:\\school\\python\\django-projects2\\envtwo\\scripts\\pip.exe'
Consider using the `--user` option or check the permissions.


(envtwo) E:\School\Python\django-projects2>python
Python 3.7.3 (v3.7.3:ef4ec6ed12, Mar 25 2019, 22:22:05) [MSC v.1916 64 bit (AMD64)] on win32
Type "help", "copyright", "credits" or "license" for more information.
>>> import django
>>> django.get_verson
Traceback (most recent call last):
  File "<stdin>", line 1, in <module>
AttributeError: module 'django' has no attribute 'get_verson'
>>> django.get_version
<function get_version at 0x0000020CA88C2048>
>>> exit()

(envtwo) E:\School\Python\django-projects2>deactivate
E:\School\Python\django-projects2>envtwo\Scripts\activate

(envtwo) E:\School\Python\django-projects2>django-admin startproject AkiraChix

(envtwo) E:\School\Python\django-projects2>dir
 Volume in drive E is New Volume
 Volume Serial Number is 94C5-AB08

 Directory of E:\School\Python\django-projects2

16/05/2019  18:58    <DIR>          .
16/05/2019  18:58    <DIR>          ..
16/05/2019  18:58    <DIR>          AkiraChix
16/05/2019  18:52    <DIR>          envtwo
               0 File(s)              0 bytes
               4 Dir(s)  639,353,962,496 bytes free

(envtwo) E:\School\Python\django-projects2>python manage.py runserver
C:\Users\dyree\AppData\Local\Programs\Python\Python37\python.exe: can't open file 'manage.py': [Errno 2] No such file or directory

(envtwo) E:\School\Python\django-projects2>dir AkiraChix
 Volume in drive E is New Volume
 Volume Serial Number is 94C5-AB08

 Directory of E:\School\Python\django-projects2\AkiraChix

16/05/2019  18:58    <DIR>          .
16/05/2019  18:58    <DIR>          ..
16/05/2019  18:58    <DIR>          AkiraChix
16/05/2019  18:58               650 manage.py
               1 File(s)            650 bytes
               3 Dir(s)  639,353,962,496 bytes free

(envtwo) E:\School\Python\django-projects2>cd AkiraChix

(envtwo) E:\School\Python\django-projects2\AkiraChix>dir AkiraChix
 Volume in drive E is New Volume
 Volume Serial Number is 94C5-AB08

 Directory of E:\School\Python\django-projects2\AkiraChix\AkiraChix

16/05/2019  18:58    <DIR>          .
16/05/2019  18:58    <DIR>          ..
16/05/2019  18:58             3,217 settings.py
16/05/2019  18:58               772 urls.py
16/05/2019  18:58               411 wsgi.py
16/05/2019  18:58                 0 __init__.py
               4 File(s)          4,400 bytes
               2 Dir(s)  639,353,962,496 bytes free

(envtwo) E:\School\Python\django-projects2\AkiraChix>cd..

(envtwo) E:\School\Python\django-projects2>dir
 Volume in drive E is New Volume
 Volume Serial Number is 94C5-AB08

 Directory of E:\School\Python\django-projects2

16/05/2019  18:58    <DIR>          .
16/05/2019  18:58    <DIR>          ..
16/05/2019  18:58    <DIR>          AkiraChix
16/05/2019  18:52    <DIR>          envtwo
               0 File(s)              0 bytes
               4 Dir(s)  639,353,962,496 bytes free

(envtwo) E:\School\Python\django-projects2>cd AkiraChix

(envtwo) E:\School\Python\django-projects2\AkiraChix>dir
 Volume in drive E is New Volume
 Volume Serial Number is 94C5-AB08

 Directory of E:\School\Python\django-projects2\AkiraChix

16/05/2019  18:58    <DIR>          .
16/05/2019  18:58    <DIR>          ..
16/05/2019  18:58    <DIR>          AkiraChix
16/05/2019  18:58               650 manage.py
               1 File(s)            650 bytes
               3 Dir(s)  639,353,962,496 bytes free

(envtwo) E:\School\Python\django-projects2\AkiraChix>python manage.py runserver
Watching for file changes with StatReloader
Performing system checks...

System check identified no issues (0 silenced).

You have 17 unapplied migration(s). Your project may not work properly until you apply the migrations for app(s): admin, auth, contenttypes, sessions.
Run 'python manage.py migrate' to apply them.
May 16, 2019 - 19:02:17
Django version 2.2.1, using settings 'AkiraChix.settings'
Starting development server at http://127.0.0.1:8000/
Quit the server with CTRL-BREAK.
[16/May/2019 19:03:12] "GET / HTTP/1.1" 200 16348
[16/May/2019 19:03:13] "GET /static/admin/css/fonts.css HTTP/1.1" 200 423
[16/May/2019 19:03:14] "GET /static/admin/fonts/Roboto-Regular-webfont.woff HTTP/1.1" 200 85876
[16/May/2019 19:03:14] "GET /static/admin/fonts/Roboto-Bold-webfont.woff HTTP/1.1" 200 86184
[16/May/2019 19:03:14] "GET /static/admin/fonts/Roboto-Light-webfont.woff HTTP/1.1" 200 85692
Not Found: /favicon.ico
[16/May/2019 19:03:14] "GET /favicon.ico HTTP/1.1" 404 1975
Traceback (most recent call last):
  File "C:\Users\dyree\AppData\Local\Programs\Python\Python37\lib\wsgiref\handlers.py", line 138, in run
    self.finish_response()
  File "C:\Users\dyree\AppData\Local\Programs\Python\Python37\lib\wsgiref\handlers.py", line 180, in finish_response
    self.write(data)
  File "C:\Users\dyree\AppData\Local\Programs\Python\Python37\lib\wsgiref\handlers.py", line 274, in write
    self.send_headers()
  File "C:\Users\dyree\AppData\Local\Programs\Python\Python37\lib\wsgiref\handlers.py", line 332, in send_headers
    self.send_preamble()
  File "C:\Users\dyree\AppData\Local\Programs\Python\Python37\lib\wsgiref\handlers.py", line 255, in send_preamble
    ('Date: %s\r\n' % format_date_time(time.time())).encode('iso-8859-1')
  File "C:\Users\dyree\AppData\Local\Programs\Python\Python37\lib\wsgiref\handlers.py", line 453, in _write
    result = self.stdout.write(data)
  File "C:\Users\dyree\AppData\Local\Programs\Python\Python37\lib\socketserver.py", line 799, in write
    self._sock.sendall(b)
ConnectionAbortedError: [WinError 10053] An established connection was aborted by the software in your host machine
[16/May/2019 19:03:14] "GET /favicon.ico HTTP/1.1" 500 59
----------------------------------------
Exception happened during processing of request from ('127.0.0.1', 62717)
Traceback (most recent call last):
  File "C:\Users\dyree\AppData\Local\Programs\Python\Python37\lib\wsgiref\handlers.py", line 138, in run
    self.finish_response()
  File "C:\Users\dyree\AppData\Local\Programs\Python\Python37\lib\wsgiref\handlers.py", line 180, in finish_response
    self.write(data)
  File "C:\Users\dyree\AppData\Local\Programs\Python\Python37\lib\wsgiref\handlers.py", line 274, in write
    self.send_headers()
  File "C:\Users\dyree\AppData\Local\Programs\Python\Python37\lib\wsgiref\handlers.py", line 332, in send_headers
    self.send_preamble()
  File "C:\Users\dyree\AppData\Local\Programs\Python\Python37\lib\wsgiref\handlers.py", line 255, in send_preamble
    ('Date: %s\r\n' % format_date_time(time.time())).encode('iso-8859-1')
  File "C:\Users\dyree\AppData\Local\Programs\Python\Python37\lib\wsgiref\handlers.py", line 453, in _write
    result = self.stdout.write(data)
  File "C:\Users\dyree\AppData\Local\Programs\Python\Python37\lib\socketserver.py", line 799, in write
    self._sock.sendall(b)
ConnectionAbortedError: [WinError 10053] An established connection was aborted by the software in your host machine

During handling of the above exception, another exception occurred:

Traceback (most recent call last):
  File "C:\Users\dyree\AppData\Local\Programs\Python\Python37\lib\wsgiref\handlers.py", line 141, in run
    self.handle_error()
  File "E:\School\Python\django-projects2\envtwo\lib\site-packages\django\core\servers\basehttp.py", line 116, in handle_error
    super().handle_error()
  File "C:\Users\dyree\AppData\Local\Programs\Python\Python37\lib\wsgiref\handlers.py", line 368, in handle_error
    self.finish_response()
  File "C:\Users\dyree\AppData\Local\Programs\Python\Python37\lib\wsgiref\handlers.py", line 180, in finish_response
    self.write(data)
  File "C:\Users\dyree\AppData\Local\Programs\Python\Python37\lib\wsgiref\handlers.py", line 274, in write
    self.send_headers()
  File "C:\Users\dyree\AppData\Local\Programs\Python\Python37\lib\wsgiref\handlers.py", line 331, in send_headers
    if not self.origin_server or self.client_is_modern():
  File "C:\Users\dyree\AppData\Local\Programs\Python\Python37\lib\wsgiref\handlers.py", line 344, in client_is_modern
    return self.environ['SERVER_PROTOCOL'].upper() != 'HTTP/0.9'
TypeError: 'NoneType' object is not subscriptable

During handling of the above exception, another exception occurred:

Traceback (most recent call last):
  File "C:\Users\dyree\AppData\Local\Programs\Python\Python37\lib\socketserver.py", line 650, in process_request_thread
    self.finish_request(request, client_address)
  File "C:\Users\dyree\AppData\Local\Programs\Python\Python37\lib\socketserver.py", line 360, in finish_request
    self.RequestHandlerClass(request, client_address, self)
  File "C:\Users\dyree\AppData\Local\Programs\Python\Python37\lib\socketserver.py", line 720, in __init__
    self.handle()
  File "E:\School\Python\django-projects2\envtwo\lib\site-packages\django\core\servers\basehttp.py", line 171, in handle
    self.handle_one_request()
  File "E:\School\Python\django-projects2\envtwo\lib\site-packages\django\core\servers\basehttp.py", line 194, in handle_one_request
    handler.run(self.server.get_app())
  File "C:\Users\dyree\AppData\Local\Programs\Python\Python37\lib\wsgiref\handlers.py", line 144, in run
    self.close()
  File "E:\School\Python\django-projects2\envtwo\lib\site-packages\django\core\servers\basehttp.py", line 111, in close
    super().close()
  File "C:\Users\dyree\AppData\Local\Programs\Python\Python37\lib\wsgiref\simple_server.py", line 35, in close
    self.status.split(' ',1)[0], self.bytes_sent
AttributeError: 'NoneType' object has no attribute 'split'
